Workbook

Sheet Summary
A1: HIPAA vs HITRUST e1 — Granular Overlap Crosswalk
A3: Source files used | C3: Metric | D3: Value | F3: Most reused control pairs
A4: HITRUST e1.csv | C4: Overlapping action items | D4: 31 | F4: HIPAA | G4: HITRUST | H4: Count
A5: HIPAA Security.csv | C5: Normalized control-pair/action-item tuples | D5: 115 | F5: REQ-1-HIPAA | G5: 0113.04a1Organizational.2 | H5: 2
C6: Distinct HIPAA ↔ HITRUST control pairs | D6: 103 | F6: REQ-12-HIPAA | G6: 0113.04a1Organizational.2 | H6: 2
C7: 1:1 action-item overlaps | D7: 6 | F7: REQ-13-HIPAA | G7: 0113.04a1Organizational.2 | H7: 2
C8: 1:Many action-item overlaps | D8: 8 | F8: REQ-17-HIPAA | G8: 1704.03b1Organizational.12 | H8: 2
C9: Many:1 action-item overlaps | D9: 9 | F9: REQ-20-HIPAA | G9: 1704.03b1Organizational.12 | H9: 2
C10: Many:Many action-item overlaps | D10: 8 | F10: REQ-26-HIPAA | G10: 10.01d1System.10 | H10: 2
F11: REQ-29-HIPAA | G11: 11.01e1System.2 | H11: 2
A12: Second pass added 45 CFR citations from public authoritative HHS/OCR and eCFR sources. Where the uploaded spreadsheets exposed only internal HIPAA control IDs (not official section labels), the workbook marks the citation as Direct, Composite, or Best-fit based on the action-item context and OCR guidance. | F12: REQ-31-HIPAA | G12: 11143.02i1Organizational.3 | H12: 2
F13: REQ-33-HIPAA | G13: 04.01x1Organizational.5 | H13: 2
F14: REQ-35-HIPAA | G14: 04.01x1Organizational.5 | H14: 2
F15: REQ-55-HIPAA | G15: 06.09b1System.2 | H15: 2
A18: How to read the tabs
A19: Action_Item_Overlap | B19: One row per shared action item, with control lists on both sides and action-level mapping cardinality.
A20: Normalized_Tuples | B20: Most granular view: one row per HIPAA control ↔ HITRUST e1 control within a shared action item.
A21: Pair_Summary | B21: Deduplicated control pairs, plus the action items where each pair appears.
A23: Second-pass 45 CFR enrichment | C23: 45 CFR metric | D23: Value
C24: Normalized tuples with added 45 CFR citations | D24: 115
C25: Distinct (HIPAA control, action item) citation mappings | D25: 57
C26: Rows with direct matches | D26: 54
C27: Rows with composite matches | D27: 11
C28: Rows with best-fit matches | D28: 50
A30: New tabs in this version
A31: HIPAA_45CFR_Mapping | B31: Unique HIPAA-control + action-item contexts with the added 45 CFR citations, confidence level, basis, and source URLs.
A32: Source_Register | B32: Register of authoritative public HHS/OCR and eCFR sources used for the citation enrichment.

Sheet Action_Item_Overlap
A1: Source File | B1: Reference ID | C1: Category | D1: Action Item | E1: HIPAA Controls | F1: HIPAA Control Count | G1: HITRUST e1 Controls | H1: HITRUST Control Count | I1: Mapping Type | J1: Overlap Notes | K1: HIPAA 45 CFR Citation(s) | L1: HIPAA Standard / Spec | M1: 45 CFR Mapping Confidence | N1: 45 CFR Mapping Basis | O1: Authoritative Public Source URL(s) | P1: 45 CFR Notes
A2: HITRUST e1.csv | B2: ER-18 | C2: Configuration | D2: Anti-malware and Alerts | E2: REQ-38-HIPAA | F2: =IF(E2="",0,LEN(E2)-LEN(SUBSTITUTE(E2,",",""))+1) -> 1 | G2: 0226.09k1Organizational.2, 08.09m1Organizational.8, 02962.09j1Organizational.5, 0207.09j1Organizational.6 | H2: =IF(G2="",0,LEN(G2)-LEN(SUBSTITUTE(G2,",",""))+1) -> 4 | I2: =IF(AND(F2=1,H2=1),"1:1",IF(AND(F2=1,H2>1),"1:Many",IF(AND(F2>1,H2=1),"Many:1","Many:Many"))) -> 1:Many | J2: =IF(I2="1:1","Direct 1:1 overlap at the action-item level.",IF(I2="1:Many","One HIPAA local control decomposes into multiple HITRUST e1 controls in this action item.",IF(I2="Many:1","Multiple HIPAA local controls converge on one HITRUST e1 control in this action item.","Composite overlap: multiple HIPAA and HITRUST e1 controls are satisfied by the same action item."))) -> One HIPAA local control decomposes into multiple HITRUST e1 controls in this action item. | K2: 45 CFR § 164.308(a)(5)(ii)(B) | L2: Security Awareness and Training — Protection from Malicious Software | M2: Direct | N2: Anti-malware evidence aligns directly to guarding against, detecting, and reporting malicious software. | O2: https://www.ecfr.gov/current/title-45/subtitle-A/subchapter-C/part-164/section-164.308 | https://www.hhs.gov/sites/default/files/ocr/privacy/hipaa/administrative/securityrule/adminsafeguards.pdf | https://www.hhs.gov/sites/default/files/ocr/privacy/hipaa/administrative/combined/hipaa-simplification-201303.pdf | P2: Alerts are treated as part of guarding against/detecting malicious software.
A3: HITRUST e1.csv | B3: ER-114 | C3: Configuration | D3: Backups and Schedules | E3: REQ-62-HIPAA, REQ-63-HIPAA | F3: =IF(E3="",0,LEN(E3)-LEN(SUBSTITUTE(E3,",",""))+1) -> 2 | G3: 1616.09l1Organizational.16, 16.09l1Organizational.4, 1618.09l1Organizational.45 | H3: =IF(G3="",0,LEN(G3)-LEN(SUBSTITUTE(G3,",",""))+1) -> 3 | I3: =IF(AND(F3=1,H3=1),"1:1",IF(AND(F3=1,H3>1),"1:Many",IF(AND(F3>1,H3=1),"Many:1","Many:Many"))) -> Many:Many | J3: =IF(I3="1:1","Direct 1:1 overlap at the action-item level.",IF(I3="1:Many","One HIPAA local control decomposes into multiple HITRUST e1 controls in this action item.",IF(I3="Many:1","Multiple HIPAA local controls converge on one HITRUST e1 control in this action item.","Composite overlap: multiple HIPAA and HITRUST e1 controls are satisfied by the same action item."))) -> Composite overlap: multiple HIPAA and HITRUST e1 controls are satisfied by the same action item. | K3: 45 CFR § 164.308(a)(7)(ii)(A) | 45 CFR § 164.308(a)(7)(ii)(B) | L3: Contingency Plan — Data Backup Plan | Contingency Plan — Disaster Recovery Plan | M3: Direct | Best-fit | N3: Backup schedules most directly align to maintaining retrievable exact copies of ePHI. | Backup/replication planning most closely aligns to restoring lost data and recovering operations after a disruption. | O3: https://www.ecfr.gov/current/title-45/subtitle-A/subchapter-C/part-164/section-164.308 | https://www.hhs.gov/hipaa/for-professionals/compliance-enforcement/audit/protocol/index.html | https://www.hhs.gov/hipaa/for-professionals/security/guidance/cybersecurity/ransomware-fact-sheet/index.html | https://www.hhs.gov/sites/default/files/ocr/privacy/hipaa/administrative/combined/hipaa-simplification-201303.pdf | P3: Used for backup schedule evidence. | Used for schedule-level backup rows when the internal control appears to emphasize recoverability/replication.
A4: HITRUST e1.csv | B4: ER-1 | C4: Configuration | D4: Data Encryption at Rest | E4: REQ-33-HIPAA, REQ-34-HIPAA, REQ-35-HIPAA | F4: =IF(E4="",0,LEN(E4)-LEN(SUBSTITUTE(E4,",",""))+1) -> 3 | G4: 04.01x1Organizational.5, 1903.06d1Organizational.3456711 | H4: =IF(G4="",0,LEN(G4)-LEN(SUBSTITUTE(G4,",",""))+1) -> 2 | I4: =IF(AND(F4=1,H4=1),"1:1",IF(AND(F4=1,H4>1),"1:Many",IF(AND(F4>1,H4=1),"Many:1","Many:Many"))) -> Many:Many | J4: =IF(I4="1:1","Direct 1:1 overlap at the action-item level.",IF(I4="1:Many","One HIPAA local control decomposes into multiple HITRUST e1 controls in this action item.",IF(I4="Many:1","Multiple HIPAA local controls converge on one HITRUST e1 control in this action item.","Composite overlap: multiple HIPAA and HITRUST e1 controls are satisfied by the same action item."))) -> Composite overlap: multiple HIPAA and HITRUST e1 controls are satisfied by the same action item. | K4: 45 CFR § 164.312(a)(2)(iv) | L4: Access Control — Encryption and Decryption | M4: Direct | Best-fit | N4: At-rest encryption evidence aligns directly to the encryption/decryption implementation specification under access control. | Control/action-item context aligns to at-rest encryption. | This internal control ID also appears on an at-rest encryption row in the source spreadsheets, so the row context points to at-rest encryption even though the same control family also covers transmission encryption elsewhere. | O4: https://www.ecfr.gov/current/title-45/subtitle-A/subchapter-C/part-164/section-164.312 | https://www.hhs.gov/hipaa/for-professionals/compliance-enforcement/audit/protocol/index.html | https://www.hhs.gov/sites/default/files/ocr/privacy/hipaa/administrative/combined/hipaa-simplification-201303.pdf | P4: Used when the shared action item is explicitly at-rest encryption. | Used for data-encryption-at-rest rows. | Row-context mapping takes precedence over the broader internal control family.
A5: HITRUST e1.csv | B5: ER-3 | C5: Configuration | D5: Encryption In Transit (Ex. TLS Protocols) | E5: REQ-33-HIPAA, REQ-35-HIPAA | F5: =IF(E5="",0,LEN(E5)-LEN(SUBSTITUTE(E5,",",""))+1) -> 2 | G5: 04.01x1Organizational.5, 0913.09s1Organizational.5, 1013.01r1System.2, 0862.09m2Organizational.8, 0928.09v2Organizational.1, 0945.09y1Organizational.3, 0954.10d1System.1, 0903.10f1Organizational.1.a | H5: =IF(G5="",0,LEN(G5)-LEN(SUBSTITUTE(G5,",",""))+1) -> 8 | I5: =IF(AND(F5=1,H5=1),"1:1",IF(AND(F5=1,H5>1),"1:Many",IF(AND(F5>1,H5=1),"Many:1","Many:Many"))) -> Many:Many | J5: =IF(I5="1:1","Direct 1:1 overlap at the action-item level.",IF(I5="1:Many","One HIPAA local control decomposes into multiple HITRUST e1 controls in this action item.",IF(I5="Many:1","Multiple HIPAA local controls converge on one HITRUST e1 control in this action item.","Composite overlap: multiple HIPAA and HITRUST e1 controls are satisfied by the same action item."))) -> Composite overlap: multiple HIPAA and HITRUST e1 controls are satisfied by the same action item. | K5: 45 CFR § 164.312(e)(2)(ii) | L5: Transmission Security — Encryption | M5: Direct | N5: Transmission-encryption evidence aligns directly to the transmission-security encryption implementation specification. | Action item explicitly addresses encryption in transit. | O5: https://www.ecfr.gov/current/title-45/subtitle-A/subchapter-C/part-164/section-164.312 | https://www.hhs.gov/sites/default/files/ocr/privacy/hipaa/administrative/combined/hipaa-simplification-201303.pdf | https://www.hhs.gov/hipaa/for-professionals/security/guidance/cybersecurity-newsletter-january-2026/index.html | P5: Used when the shared action item is explicitly in-transit encryption. | Used for transport/TLS evidence.
A6: HITRUST e1.csv | B6: ER-88 | C6: Configuration | D6: Evidence of Multi-Factor Authentication | E6: REQ-27-HIPAA | F6: =IF(E6="",0,LEN(E6)-LEN(SUBSTITUTE(E6,",",""))+1) -> 1 | G6: 11.01q1System.3, 11.01q1System.4 | H6: =IF(G6="",0,LEN(G6)-LEN(SUBSTITUTE(G6,",",""))+1) -> 2 | I6: =IF(AND(F6=1,H6=1),"1:1",IF(AND(F6=1,H6>1),"1:Many",IF(AND(F6>1,H6=1),"Many:1","Many:Many"))) -> 1:Many | J6: =IF(I6="1:1","Direct 1:1 overlap at the action-item level.",IF(I6="1:Many","One HIPAA local control decomposes into multiple HITRUST e1 controls in this action item.",IF(I6="Many:1","Multiple HIPAA local controls converge on one HITRUST e1 control in this action item.","Composite overlap: multiple HIPAA and HITRUST e1 controls are satisfied by the same action item."))) -> One HIPAA local control decomposes into multiple HITRUST e1 controls in this action item. | K6: 45 CFR § 164.312(d) | L6: Person or Entity Authentication | M6: Direct | N6: MFA evidence most directly supports verifying that the person or entity seeking access is the one claimed. | O6: https://www.ecfr.gov/current/title-45/subtitle-A/subchapter-C/part-164/section-164.312 | https://www.hhs.gov/hipaa/for-professionals/compliance-enforcement/audit/protocol/index.html | https://www.hhs.gov/hipaa/for-professionals/security/guidance/cybersecurity-newsletter-january-2026/index.html | P6: HIPAA does not mandate a specific technology such as MFA in all cases, but MFA evidence is a strong implementation of this standard.
A7: HITRUST e1.csv | B7: ER-91 | C7: Configuration | D7: Firewall Rules/Security Groups | E7: REQ-37-HIPAA | F7: =IF(E7="",0,LEN(E7)-LEN(SUBSTITUTE(E7,",",""))+1) -> 1 | G7: 0265.09m1Organizational.2, 0805.01m1Organizational.12 | H7: =IF(G7="",0,LEN(G7)-LEN(SUBSTITUTE(G7,",",""))+1) -> 2 | I7: =IF(AND(F7=1,H7=1),"1:1",IF(AND(F7=1,H7>1),"1:Many",IF(AND(F7>1,H7=1),"Many:1","Many:Many"))) -> 1:Many | J7: =IF(I7="1:1","Direct 1:1 overlap at the action-item level.",IF(I7="1:Many","One HIPAA local control decomposes into multiple HITRUST e1 controls in this action item.",IF(I7="Many:1","Multiple HIPAA local controls converge on one HITRUST e1 control in this action item.","Composite overlap: multiple HIPAA and HITRUST e1 controls are satisfied by the same action item."))) -> One HIPAA local control decomposes into multiple HITRUST e1 controls in this action item. | K7: 45 CFR § 164.312(a)(1) | L7: Access Control | M7: Best-fit | N7: Firewall rules/security groups are a technical means of enforcing access restrictions around systems containing ePHI. | O7: https://www.ecfr.gov/current/title-45/subtitle-A/subchapter-C/part-164/section-164.312 | https://www.hhs.gov/hipaa/for-professionals/compliance-enforcement/audit/protocol/index.html | https://www.hhs.gov/hipaa/for-professionals/security/guidance/cybersecurity-newsletter-summer-2019/index.html | P7: Mapped to the broad access-control standard because HIPAA does not list firewall rules as a separate named specification.
A8: HITRUST e1.csv | B8: ER-12 | C8: Configuration | D8: List of All Production Systems (Servers, VMs, Data Stores) | E8: REQ-33-HIPAA, REQ-34-HIPAA, REQ-43-HIPAA, REQ-102-HIPAA | F8: =IF(E8="",0,LEN(E8)-LEN(SUBSTITUTE(E8,",",""))+1) -> 4 | G8: 0701.07a1Organizational.8, 0701.07a1Organizational.7, 07.07a1Organizational.8 | H8: =IF(G8="",0,LEN(G8)-LEN(SUBSTITUTE(G8,",",""))+1) -> 3 | I8: =IF(AND(F8=1,H8=1),"1:1",IF(AND(F8=1,H8>1),"1:Many",IF(AND(F8>1,H8=1),"Many:1","Many:Many"))) -> Many:Many | J8: =IF(I8="1:1","Direct 1:1 overlap at the action-item level.",IF(I8="1:Many","One HIPAA local control decomposes into multiple HITRUST e1 controls in this action item.",IF(I8="Many:1","Multiple HIPAA local controls converge on one HITRUST e1 control in this action item.","Composite overlap: multiple HIPAA and HITRUST e1 controls are satisfied by the same action item."))) -> Composite overlap: multiple HIPAA and HITRUST e1 controls are satisfied by the same action item. | K8: 45 CFR § 164.308(a)(1)(ii)(A) | 45 CFR § 164.312(a)(2)(iv) | 45 CFR § 164.312(e)(2)(ii) | 45 CFR § 164.308(a)(1)(ii)(B) | L8: Security Management Process — Risk Analysis | Access Control — Encryption and Decryption | Transmission Security — Encryption | Security Management Process — Risk Management | M8: Best-fit composite | Best-fit | N8: System-inventory evidence is not explicitly named in the Security Rule, but OCR guidance treats asset inventories and system scoping as supporting accurate risk analysis and implementation of encryption safeguards. | System inventory supports scoping/coverage of at-rest encryption and accurate risk analysis. | A production-systems inventory is supporting evidence for patch coverage and vulnerability scoping under risk analysis/risk management. | HIPAA does not expressly mandate an IT asset inventory, but OCR guidance says a comprehensive technology asset inventory and ePHI data-flow diagrams are valuable tools for an accurate and thorough risk analysis. | O8: https://www.ecfr.gov/current/title-45/subtitle-A/subchapter-C/part-164/section-164.308 | https://www.ecfr.gov/current/title-45/subtitle-A/subchapter-C/part-164/section-164.312 | https://www.hhs.gov/hipaa/for-professionals/security/guidance/guidance-risk-analysis/index.html | https://www.hhs.gov/hipaa/for-professionals/security/guidance/cybersecurity-newsletter-october-2024/index.html | https://www.hhs.gov/hipaa/for-professionals/security/guidance/cybersecurity-newsletter-january-2026/index.html | P8: Inventory/list-of-systems evidence is supporting evidence for encryption coverage, not a standalone named HIPAA inventory mandate. | Asset inventory is supporting evidence rather than an explicit standalone at-rest-encryption requirement. | OCR guidance treats a technology asset inventory as a valuable tool for accurate and thorough risk analysis. | Mapped as supporting evidence for risk analysis rather than as a standalone named HIPAA inventory control.
A9: HITRUST e1.csv | B9: ER-83 | C9: Configuration | D9: Network Diagram and Segmentation | E9: REQ-36-HIPAA | F9: =IF(E9="",0,LEN(E9)-LEN(SUBSTITUTE(E9,",",""))+1) -> 1 | G9: 0805.01m1Organizational.12, 0504.09m1Organizational.13 | H9: =IF(G9="",0,LEN(G9)-LEN(SUBSTITUTE(G9,",",""))+1) -> 2 | I9: =IF(AND(F9=1,H9=1),"1:1",IF(AND(F9=1,H9>1),"1:Many",IF(AND(F9>1,H9=1),"Many:1","Many:Many"))) -> 1:Many | J9: =IF(I9="1:1","Direct 1:1 overlap at the action-item level.",IF(I9="1:Many","One HIPAA local control decomposes into multiple HITRUST e1 controls in this action item.",IF(I9="Many:1","Multiple HIPAA local controls converge on one HITRUST e1 control in this action item.","Composite overlap: multiple HIPAA and HITRUST e1 controls are satisfied by the same action item."))) -> One HIPAA local control decomposes into multiple HITRUST e1 controls in this action item. | K9: 45 CFR § 164.312(a)(1) | L9: Access Control | M9: Best-fit | N9: HIPAA does not explicitly name network segmentation, but OCR guidance and enforcement materials cite segmentation as a way to implement access control between systems. | O9: https://www.ecfr.gov/current/title-45/subtitle-A/subchapter-C/part-164/section-164.312 | https://www.hhs.gov/hipaa/for-professionals/security/guidance/cybersecurity-newsletter-january-2026/index.html | https://www.hhs.gov/hipaa/for-professionals/security/guidance/cybersecurity-newsletter-summer-2019/index.html | P9: Mapped as an access-control implementation example rather than a standalone named HIPAA implementation specification.
A10: HITRUST e1.csv | B10: ER-67 | C10: Configuration | D10: Password Vault and Shared Accounts | E10: REQ-28-HIPAA, REQ-31-HIPAA | F10: =IF(E10="",0,LEN(E10)-LEN(SUBSTITUTE(E10,",",""))+1) -> 2 | G10: 1123.01q1System.2 | H10: =IF(G10="",0,LEN(G10)-LEN(SUBSTITUTE(G10,",",""))+1) -> 1 | I10: =IF(AND(F10=1,H10=1),"1:1",IF(AND(F10=1,H10>1),"1:Many",IF(AND(F10>1,H10=1),"Many:1","Many:Many"))) -> Many:1 | J10: =IF(I10="1:1","Direct 1:1 overlap at the action-item level.",IF(I10="1:Many","One HIPAA local control decomposes into multiple HITRUST e1 controls in this action item.",IF(I10="Many:1","Multiple HIPAA local controls converge on one HITRUST e1 control in this action item.","Composite overlap: multiple HIPAA and HITRUST e1 controls are satisfied by the same action item."))) -> Multiple HIPAA local controls converge on one HITRUST e1 control in this action item. | K10: 45 CFR § 164.312(a)(2)(i) | 45 CFR § 164.308(a)(4)(ii)(C) | 45 CFR § 164.308(a)(3)(ii)(C) | L10: Access Control — Unique User Identification | Information Access Management — Access Establishment and Modification | Workforce Security — Termination Procedures | M10: Composite | N10: Password-vault/shared-account and privileged-access evidence supports unique attribution of user activity and management of privileged rights. | Shared-account and privileged-access listings support timely removal of departing users and accountability for access tied to individuals. | O10: https://www.ecfr.gov/current/title-45/subtitle-A/subchapter-C/part-164/section-164.312 | https://www.ecfr.gov/current/title-45/subtitle-A/subchapter-C/part-164/section-164.308 | https://www.hhs.gov/hipaa/for-professionals/compliance-enforcement/audit/protocol/index.html | https://www.hhs.gov/sites/default/files/ocr/privacy/hipaa/administrative/securityrule/adminsafeguards.pdf | https://www.hhs.gov/hipaa/for-professionals/security/guidance/cybersecurity-newsletter-summer-2019/index.html | P10: Shared or generic-account controls are best matched to unique user identification, with access-right administration as a secondary basis. | Best read as supporting evidence that terminated users are removed from shared/privileged access paths.
A11: HITRUST e1.csv | B11: ER-25 | C11: Configuration | D11: Passwords for All In-Scope Production Systems | E11: REQ-26-HIPAA | F11: =IF(E11="",0,LEN(E11)-LEN(SUBSTITUTE(E11,",",""))+1) -> 1 | G11: 10.01d1System.10 | H11: =IF(G11="",0,LEN(G11)-LEN(SUBSTITUTE(G11,",",""))+1) -> 1 | I11: =IF(AND(F11=1,H11=1),"1:1",IF(AND(F11=1,H11>1),"1:Many",IF(AND(F11>1,H11=1),"Many:1","Many:Many"))) -> 1:1 | J11: =IF(I11="1:1","Direct 1:1 overlap at the action-item level.",IF(I11="1:Many","One HIPAA local control decomposes into multiple HITRUST e1 controls in this action item.",IF(I11="Many:1","Multiple HIPAA local controls converge on one HITRUST e1 control in this action item.","Composite overlap: multiple HIPAA and HITRUST e1 controls are satisfied by the same action item."))) -> Direct 1:1 overlap at the action-item level. | K11: 45 CFR § 164.308(a)(5)(ii)(D) | 45 CFR § 164.312(a)(1) | L11: Security Awareness and Training — Password Management | Access Control | M11: Composite | N11: Password configuration evidence most directly aligns to password-management requirements and the broader access-control standard. | O11: https://www.ecfr.gov/current/title-45/subtitle-A/subchapter-C/part-164/section-164.308 | https://www.ecfr.gov/current/title-45/subtitle-A/subchapter-C/part-164/section-164.312 | https://www.hhs.gov/sites/default/files/ocr/privacy/hipaa/administrative/securityrule/adminsafeguards.pdf | https://www.hhs.gov/hipaa/for-professionals/compliance-enforcement/audit/protocol/index.html | P11: This row is password-configuration evidence; MFA is not the primary evidence artifact here.
A12: HIPAA Security.csv | B12: ER-271 | C12: Operational | D12: Asset Custody Log | E12: REQ-109-HIPAA | F12: =IF(E12="",0,LEN(E12)-LEN(SUBSTITUTE(E12,",",""))+1) -> 1 | G12: 0704.07a1Organizational.8, 0701.07a1Organizational.8 | H12: =IF(G12="",0,LEN(G12)-LEN(SUBSTITUTE(G12,",",""))+1) -> 2 | I12: =IF(AND(F12=1,H12=1),"1:1",IF(AND(F12=1,H12>1),"1:Many",IF(AND(F12>1,H12=1),"Many:1","Many:Many"))) -> 1:Many | J12: =IF(I12="1:1","Direct 1:1 overlap at the action-item level.",IF(I12="1:Many","One HIPAA local control decomposes into multiple HITRUST e1 controls in this action item.",IF(I12="Many:1","Multiple HIPAA local controls converge on one HITRUST e1 control in this action item.","Composite overlap: multiple HIPAA and HITRUST e1 controls are satisfied by the same action item."))) -> One HIPAA local control decomposes into multiple HITRUST e1 controls in this action item. | K12: 45 CFR § 164.310(d)(2)(iii) | L12: Device and Media Controls — Accountability | M12: Direct | N12: Asset custody logs align directly to maintaining a record of the movements of hardware/electronic media and the person responsible. | O12: https://www.ecfr.gov/current/title-45/subtitle-A/subchapter-C/part-164/section-164.310 | https://www.hhs.gov/hipaa/for-professionals/compliance-enforcement/audit/protocol/index.html | https://www.hhs.gov/sites/default/files/ocr/privacy/hipaa/administrative/combined/hipaa-simplification-201303.pdf | P12: Used for custody/chain-of-responsibility evidence.
A13: HITRUST e1.csv | B13: ER-123 | C13: Operational | D13: Completed Production Data Backup Test | E13: REQ-61-HIPAA | F13: =IF(E13="",0,LEN(E13)-LEN(SUBSTITUTE(E13,",",""))+1) -> 1 | G13: 1616.09l1Organizational.16 | H13: =IF(G13="",0,LEN(G13)-LEN(SUBSTITUTE(G13,",",""))+1) -> 1 | I13: =IF(AND(F13=1,H13=1),"1:1",IF(AND(F13=1,H13>1),"1:Many",IF(AND(F13>1,H13=1),"Many:1","Many:Many"))) -> 1:1 | J13: =IF(I13="1:1","Direct 1:1 overlap at the action-item level.",IF(I13="1:Many","One HIPAA local control decomposes into multiple HITRUST e1 controls in this action item.",IF(I13="Many:1","Multiple HIPAA local controls converge on one HITRUST e1 control in this action item.","Composite overlap: multiple HIPAA and HITRUST e1 controls are satisfied by the same action item."))) -> Direct 1:1 overlap at the action-item level. | K13: 45 CFR § 164.308(a)(7)(ii)(D) | L13: Contingency Plan — Testing and Revision Procedure | M13: Direct | N13: A completed backup test aligns directly to periodic testing/revision of contingency plans. | O13: https://www.ecfr.gov/current/title-45/subtitle-A/subchapter-C/part-164/section-164.308 | https://www.hhs.gov/hipaa/for-professionals/compliance-enforcement/audit/protocol/index.html | https://www.hhs.gov/hipaa/for-professionals/security/guidance/cybersecurity/ransomware-fact-sheet/index.html | P13: Used for explicit backup-test evidence.
... A32: HITRUST e1.csv | B32: ER-62 | C32: Sample | D32: Software/Infrastructure Production Change Ticket | E32: REQ-55-HIPAA | F32: =IF(E32="",0,LEN(E32)-LEN(SUBSTITUTE(E32,",",""))+1) -> 1 | G32: 06.09b1System.2 | H32: =IF(G32="",0,LEN(G32)-LEN(SUBSTITUTE(G32,",",""))+1) -> 1 | I32: =IF(AND(F32=1,H32=1),"1:1",IF(AND(F32=1,H32>1),"1:Many",IF(AND(F32>1,H32=1),"Many:1","Many:Many"))) -> 1:1 | J32: =IF(I32="1:1","Direct 1:1 overlap at the action-item level.",IF(I32="1:Many","One HIPAA local control decomposes into multiple HITRUST e1 controls in this action item.",IF(I32="Many:1","Multiple HIPAA local controls converge on one HITRUST e1 control in this action item.","Composite overlap: multiple HIPAA and HITRUST e1 controls are satisfied by the same action item."))) -> Direct 1:1 overlap at the action-item level. | K32: 45 CFR § 164.308(a)(8) | 45 CFR § 164.316(b)(1) | L32: Evaluation | Documentation | M32: Best-fit composite | N32: Production-change tickets/population evidence are not a named HIPAA specification, but they are strong evidence of evaluating and documenting operational changes affecting ePHI safeguards. | O32: https://www.ecfr.gov/current/title-45/subtitle-A/subchapter-C/part-164/section-164.308 | https://www.ecfr.gov/current/title-45/subtitle-A/subchapter-C/part-164/section-164.316 | https://www.hhs.gov/hipaa/for-professionals/security/guidance/cybersecurity-newsletter-january-2026/index.html | https://www.hhs.gov/hipaa/for-professionals/security/guidance/guidance-risk-analysis/index.html | P32: Best-fit evidence mapping; HIPAA does not mandate a particular ticketing mechanism.

Sheet Normalized_Tuples
A1: Source File | B1: Reference ID | C1: Category | D1: Action Item | E1: HIPAA Control | F1: HITRUST e1 Control | G1: Action-Item Mapping Type | H1: Pair Reuse Count | I1: HIPAA 45 CFR Citation(s) | J1: HIPAA Standard / Spec | K1: 45 CFR Mapping Confidence | L1: 45 CFR Mapping Basis | M1: Authoritative Public Source URL(s) | N1: 45 CFR Notes
A2: HITRUST e1.csv | B2: ER-86 | C2: Policy | D2: Access Control | E2: REQ-24-HIPAA | F2: 11.01e1System.2 | G2: Many:1 | H2: =COUNTIFS($E:$E,E2,$F:$F,F2) -> 1 | I2: 45 CFR § 164.312(a)(1); 45 CFR § 164.308(a)(4)(i) | J2: Access Control; Information Access Management | K2: Composite | L2: Broad access-control policy control spans both the technical access-control standard and the administrative information-access-management standard. | M2: https://www.ecfr.gov/current/title-45/subtitle-A/subchapter-C/part-164/section-164.312 | https://www.ecfr.gov/current/title-45/subtitle-A/subchapter-C/part-164/section-164.308 | https://www.hhs.gov/hipaa/for-professionals/compliance-enforcement/audit/protocol/index.html | https://www.hhs.gov/sites/default/files/ocr/privacy/hipaa/administrative/combined/hipaa-simplification-201303.pdf | N2: Used when the spreadsheet row is a general access-control policy without a narrower authorization/review/termination artifact.
A3: HITRUST e1.csv | B3: ER-86 | C3: Policy | D3: Access Control | E3: REQ-29-HIPAA | F3: 11.01e1System.2 | G3: Many:1 | H3: =COUNTIFS($E:$E,E3,$F:$F,F3) -> 2 | I3: 45 CFR § 164.308(a)(4)(ii)(C) | J3: Information Access Management — Access Establishment and Modification | K3: Direct | L3: Access-review documentation aligns directly to the requirement to establish, document, review, and modify user rights of access. | M3: https://www.ecfr.gov/current/title-45/subtitle-A/subchapter-C/part-164/section-164.308 | https://www.hhs.gov/hipaa/for-professionals/compliance-enforcement/audit/protocol/index.html | https://www.hhs.gov/sites/default/files/ocr/privacy/hipaa/administrative/securityrule/adminsafeguards.pdf | N3: Used for both access-review evidence and broader policy statements that emphasize periodic review/modification.
A4: HITRUST e1.csv | B4: ER-86 | C4: Policy | D4: Access Control | E4: REQ-30-HIPAA | F4: 11.01e1System.2 | G4: Many:1 | H4: =COUNTIFS($E:$E,E4,$F:$F,F4) -> 1 | I4: 45 CFR § 164.308(a)(4)(ii)(B) | J4: Information Access Management — Access Authorization | K4: Direct | L4: New-hire access request and approval evidence aligns directly to access authorization. | M4: https://www.ecfr.gov/current/title-45/subtitle-A/subchapter-C/part-164/section-164.308 | https://www.hhs.gov/hipaa/for-professionals/compliance-enforcement/audit/protocol/index.html | https://www.hhs.gov/sites/default/files/ocr/privacy/hipaa/administrative/securityrule/adminsafeguards.pdf | N4: Used for access-request forms/templates and access-control rows that center on approvals.
A5: HITRUST e1.csv | B5: ER-86 | C5: Policy | D5: Access Control | E5: REQ-31-HIPAA | F5: 11.01e1System.2 | G5: Many:1 | H5: =COUNTIFS($E:$E,E5,$F:$F,F5) -> 1 | I5: 45 CFR § 164.308(a)(3)(ii)(C); 45 CFR § 164.308(a)(4)(ii)(C) | J5: Workforce Security — Termination Procedures; Information Access Management — Access Establishment and Modification | K5: Composite | L5: The same internal control appears within a general access-control policy row; termination remains the most likely HIPAA basis, with access-right modification as supporting context. | M5: https://www.ecfr.gov/current/title-45/subtitle-A/subchapter-C/part-164/section-164.308 | https://www.hhs.gov/hipaa/for-professionals/compliance-enforcement/audit/protocol/index.html | https://www.hhs.gov/hipaa/for-professionals/security/guidance/cybersecurity-newsletter-summer-2019/index.html | N5: Mapped conservatively because the internal control ID spans both termination evidence and access-control policy language.
A6: HITRUST e1.csv | B6: ER-87 | C6: Sample | D6: Access Review Documentation | E6: REQ-29-HIPAA | F6: 11.01e1System.2 | G6: 1:1 | H6: =COUNTIFS($E:$E,E6,$F:$F,F6) -> 2 | I6: 45 CFR § 164.308(a)(4)(ii)(C) | J6: Information Access Management — Access Establishment and Modification | K6: Direct | L6: Access-review documentation aligns directly to the requirement to establish, document, review, and modify user rights of access. | M6: https://www.ecfr.gov/current/title-45/subtitle-A/subchapter-C/part-164/section-164.308 | https://www.hhs.gov/hipaa/for-professionals/compliance-enforcement/audit/protocol/index.html | https://www.hhs.gov/sites/default/files/ocr/privacy/hipaa/administrative/securityrule/adminsafeguards.pdf | N6: Used for both access-review evidence and broader policy statements that emphasize periodic review/modification.
A7: HITRUST e1.csv | B7: ER-141 | C7: Population | D7: All Incidents Identified During the Review Period [INSERT EXAM PERIOD] | E7: REQ-50-HIPAA | F7: 1561.11c1Organizational.4 | G7: Many:1 | H7: =COUNTIFS($E:$E,E7,$F:$F,F7) -> 1 | I7: 45 CFR § 164.308(a)(6)(ii); 45 CFR § 164.316(b)(1) | J7: Security Incident Procedures — Response and Reporting; Documentation | K7: Composite | L7: Incident tickets/population evidence show response/reporting activities and the required documentation of incidents and outcomes. | M7: https://www.ecfr.gov/current/title-45/subtitle-A/subchapter-C/part-164/section-164.308 | https://www.ecfr.gov/current/title-45/subtitle-A/subchapter-C/part-164/section-164.316 | https://www.hhs.gov/hipaa/for-professionals/faq/2002/what-does-the-security-rule-require-a-covered-entity-to-do-to-comply/index.html | https://www.hhs.gov/hipaa/for-professionals/compliance-enforcement/audit/protocol/index.html | N7: Documentation is added because the evidence row is a ticket/log of incidents during the review period.
A8: HITRUST e1.csv | B8: ER-141 | C8: Population | D8: All Incidents Identified During the Review Period [INSERT EXAM PERIOD] | E8: REQ-995-HIPAA | F8: 1561.11c1Organizational.4 | G8: Many:1 | H8: =COUNTIFS($E:$E,E8,$F:$F,F8) -> 1 | I8: 45 CFR § 164.308(a)(6)(ii); 45 CFR § 164.316(b)(1) | J8: Security Incident Procedures — Response and Reporting; Documentation | K8: Best-fit composite | L8: Generic population/evidence control used to show incidents and outcomes during the review period. | M8: https://www.ecfr.gov/current/title-45/subtitle-A/subchapter-C/part-164/section-164.308 | https://www.ecfr.gov/current/title-45/subtitle-A/subchapter-C/part-164/section-164.316 | https://www.hhs.gov/hipaa/for-professionals/faq/2002/what-does-the-security-rule-require-a-covered-entity-to-do-to-comply/index.html | https://www.hhs.gov/hipaa/for-professionals/compliance-enforcement/audit/protocol/index.html | N8: Internal control is generic; citation follows the specific evidence row context.
A9: HITRUST e1.csv | B9: ER-139 | C9: Population | D9: All Software and Infrastructure Production Changes During the Review Period [INSERT EXAM PERIOD] | E9: REQ-55-HIPAA | F9: 06.09b1System.2 | G9: Many:Many | H9: =COUNTIFS($E:$E,E9,$F:$F,F9) -> 2 | I9: 45 CFR § 164.308(a)(8); 45 CFR § 164.316(b)(1) | J9: Evaluation; Documentation | K9: Best-fit composite | L9: Production-change tickets/population evidence are not a named HIPAA specification, but they are strong evidence of evaluating and documenting operational changes affecting ePHI safeguards. | M9: https://www.ecfr.gov/current/title-45/subtitle-A/subchapter-C/part-164/section-164.308 | https://www.ecfr.gov/current/title-45/subtitle-A/subchapter-C/part-164/section-164.316 | https://www.hhs.gov/hipaa/for-professionals/security/guidance/cybersecurity-newsletter-january-2026/index.html | https://www.hhs.gov/hipaa/for-professionals/security/guidance/guidance-risk-analysis/index.html | N9: Best-fit evidence mapping; HIPAA does not mandate a particular ticketing mechanism.
A10: HITRUST e1.csv | B10: ER-139 | C10: Population | D10: All Software and Infrastructure Production Changes During the Review Period [INSERT EXAM PERIOD] | E10: REQ-55-HIPAA | F10: 1704.03b1Organizational.12 | G10: Many:Many | H10: =COUNTIFS($E:$E,E10,$F:$F,F10) -> 1 | I10: 45 CFR § 164.308(a)(8); 45 CFR § 164.316(b)(1) | J10: Evaluation; Documentation | K10: Best-fit composite | L10: Production-change tickets/population evidence are not a named HIPAA specification, but they are strong evidence of evaluating and documenting operational changes affecting ePHI safeguards. | M10: https://www.ecfr.gov/current/title-45/subtitle-A/subchapter-C/part-164/section-164.308 | https://www.ecfr.gov/current/title-45/subtitle-A/subchapter-C/part-164/section-164.316 | https://www.hhs.gov/hipaa/for-professionals/security/guidance/cybersecurity-newsletter-january-2026/index.html | https://www.hhs.gov/hipaa/for-professionals/security/guidance/guidance-risk-analysis/index.html | N10: Best-fit evidence mapping; HIPAA does not mandate a particular ticketing mechanism.
A11: HITRUST e1.csv | B11: ER-139 | C11: Population | D11: All Software and Infrastructure Production Changes During the Review Period [INSERT EXAM PERIOD] | E11: REQ-995-HIPAA | F11: 06.09b1System.2 | G11: Many:Many | H11: =COUNTIFS($E:$E,E11,$F:$F,F11) -> 1 | I11: 45 CFR § 164.308(a)(8); 45 CFR § 164.316(b)(1) | J11: Evaluation; Documentation | K11: Best-fit composite | L11: Generic population/evidence control used to show production changes during the review period. | M11: https://www.ecfr.gov/current/title-45/subtitle-A/subchapter-C/part-164/section-164.308 | https://www.ecfr.gov/current/title-45/subtitle-A/subchapter-C/part-164/section-164.316 | https://www.hhs.gov/hipaa/for-professionals/security/guidance/cybersecurity-newsletter-january-2026/index.html | https://www.hhs.gov/hipaa/for-professionals/security/guidance/guidance-risk-analysis/index.html | N11: Internal control is generic; citation follows the specific evidence row context.
A12: HITRUST e1.csv | B12: ER-139 | C12: Population | D12: All Software and Infrastructure Production Changes During the Review Period [INSERT EXAM PERIOD] | E12: REQ-995-HIPAA | F12: 1704.03b1Organizational.12 | G12: Many:Many | H12: =COUNTIFS($E:$E,E12,$F:$F,F12) -> 1 | I12: 45 CFR § 164.308(a)(8); 45 CFR § 164.316(b)(1) | J12: Evaluation; Documentation | K12: Best-fit composite | L12: Generic population/evidence control used to show production changes during the review period. | M12: https://www.ecfr.gov/current/title-45/subtitle-A/subchapter-C/part-164/section-164.308 | https://www.ecfr.gov/current/title-45/subtitle-A/subchapter-C/part-164/section-164.316 | https://www.hhs.gov/hipaa/for-professionals/security/guidance/cybersecurity-newsletter-january-2026/index.html | https://www.hhs.gov/hipaa/for-professionals/security/guidance/guidance-risk-analysis/index.html | N12: Internal control is generic; citation follows the specific evidence row context.
A13: HITRUST e1.csv | B13: ER-136 | C13: Population | D13: All Terminated Employees During the Review Period [INSERT EXAM PERIOD] | E13: REQ-31-HIPAA | F13: 11143.02i1Organizational.3 | G13: Many:1 | H13: =COUNTIFS($E:$E,E13,$F:$F,F13) -> 2 | I13: 45 CFR § 164.308(a)(3)(ii)(C); 45 CFR § 164.316(b)(1) | J13: Workforce Security — Termination Procedures; Documentation | K13: Composite | L13: Termination tickets/population evidence align directly to terminating access and documenting the action taken. | M13: https://www.ecfr.gov/current/title-45/subtitle-A/subchapter-C/part-164/section-164.308 | https://www.ecfr.gov/current/title-45/subtitle-A/subchapter-C/part-164/section-164.316 | https://www.hhs.gov/hipaa/for-professionals/compliance-enforcement/audit/protocol/index.html | https://www.hhs.gov/hipaa/for-professionals/security/guidance/cybersecurity-newsletter-summer-2019/index.html | N13: Documentation is added because the row is explicit evidence that access-removal events were carried out and recorded.
... A116: HITRUST e1.csv | B116: ER-62 | C116: Sample | D116: Software/Infrastructure Production Change Ticket | E116: REQ-55-HIPAA | F116: 06.09b1System.2 | G116: 1:1 | H116: =COUNTIFS($E:$E,E116,$F:$F,F116) -> 2 | I116: 45 CFR § 164.308(a)(8); 45 CFR § 164.316(b)(1) | J116: Evaluation; Documentation | K116: Best-fit composite | L116: Production-change tickets/population evidence are not a named HIPAA specification, but they are strong evidence of evaluating and documenting operational changes affecting ePHI safeguards. | M116: https://www.ecfr.gov/current/title-45/subtitle-A/subchapter-C/part-164/section-164.308 | https://www.ecfr.gov/current/title-45/subtitle-A/subchapter-C/part-164/section-164.316 | https://www.hhs.gov/hipaa/for-professionals/security/guidance/cybersecurity-newsletter-january-2026/index.html | https://www.hhs.gov/hipaa/for-professionals/security/guidance/guidance-risk-analysis/index.html | N116: Best-fit evidence mapping; HIPAA does not mandate a particular ticketing mechanism.

Sheet Pair_Summary
A1: HIPAA Control | B1: HITRUST e1 Control | C1: Action Item Count | D1: Action Items | E1: Categories | F1: Source Files | G1: Mapping Types Seen | H1: HIPAA 45 CFR Citation(s) | I1: HIPAA Standard / Spec | J1: 45 CFR Mapping Confidence | K1: 45 CFR Mapping Basis | L1: Authoritative Public Source URL(s) | M1: 45 CFR Notes
A2: REQ-1-HIPAA | B2: 0113.04a1Organizational.2 | C2: =COUNTIFS(Normalized_Tuples!$E:$E,$A2,Normalized_Tuples!$F:$F,$B2) -> 2 | D2: Information Security; Information Security Policy Repository | E2: Policy, Operational | F2: HITRUST e1.csv | G2: Many:1 | H2: 45 CFR § 164.316(a) | 45 CFR § 164.316(b)(1) | I2: Policies and Procedures | Documentation | J2: Best-fit (broad policy control) | K2: Internal control/action item is a general information-security policy repository rather than a single named HIPAA implementation specification; mapped to the Security Rule's policies/procedures and documentation requirements. | L2: https://www.ecfr.gov/current/title-45/subtitle-A/subchapter-C/part-164/section-164.316 | https://www.hhs.gov/sites/default/files/ocr/privacy/hipaa/administrative/securityrule/pprequirements.pdf | https://www.hhs.gov/ocr/privacy/hipaa/administrative/securityrule/index.html | M2: Used as the umbrella HIPAA citation for documented security policies. This is broader than any single safeguard requirement.
A3: REQ-12-HIPAA | B3: 0113.04a1Organizational.2 | C3: =COUNTIFS(Normalized_Tuples!$E:$E,$A3,Normalized_Tuples!$F:$F,$B3) -> 2 | D3: Information Security; Information Security Policy Repository | E3: Policy, Operational | F3: HITRUST e1.csv | G3: Many:1 | H3: 45 CFR § 164.308(a)(5) | I3: Security Awareness and Training | J3: Direct | K3: Action item and control context align to workforce security-awareness training for new hires. | L3: https://www.ecfr.gov/current/title-45/subtitle-A/subchapter-C/part-164/section-164.308 | https://www.hhs.gov/sites/default/files/ocr/privacy/hipaa/administrative/combined/hipaa-simplification-201303.pdf | https://www.hhs.gov/sites/default/files/ocr/privacy/hipaa/administrative/securityrule/adminsafeguards.pdf | M3: Mapped at the standard level because the spreadsheet does not break new-hire training into the more granular addressable sub-specifications.
A4: REQ-13-HIPAA | B4: 0113.04a1Organizational.2 | C4: =COUNTIFS(Normalized_Tuples!$E:$E,$A4,Normalized_Tuples!$F:$F,$B4) -> 2 | D4: Information Security; Information Security Policy Repository | E4: Policy, Operational | F4: HITRUST e1.csv | G4: Many:1 | H4: 45 CFR § 164.308(a)(5) | I4: Security Awareness and Training | J4: Direct | K4: Action item and control context align to ongoing/current-employee security-awareness training. | L4: https://www.ecfr.gov/current/title-45/subtitle-A/subchapter-C/part-164/section-164.308 | https://www.hhs.gov/sites/default/files/ocr/privacy/hipaa/administrative/combined/hipaa-simplification-201303.pdf | https://www.hhs.gov/sites/default/files/ocr/privacy/hipaa/administrative/securityrule/adminsafeguards.pdf | M4: Mapped at the standard level because the spreadsheet expresses periodic training broadly, not only reminders or phishing-specific sub-controls.
A5: REQ-17-HIPAA | B5: 1704.03b1Organizational.12 | C5: =COUNTIFS(Normalized_Tuples!$E:$E,$A5,Normalized_Tuples!$F:$F,$B5) -> 2 | D5: Risk Assessment; Risk Management | E5: Operational, Policy | F5: HITRUST e1.csv | G5: Many:1, Many:Many | H5: 45 CFR § 164.308(a)(1)(ii)(A) | I5: Security Management Process — Risk Analysis | J5: Direct | K5: Control context aligns to identifying risks and vulnerabilities to ePHI. | L5: https://www.ecfr.gov/current/title-45/subtitle-A/subchapter-C/part-164/section-164.308 | https://www.hhs.gov/sites/default/files/ocr/privacy/hipaa/administrative/combined/hipaa-simplification-201303.pdf | https://www.hhs.gov/hipaa/for-professionals/security/guidance/guidance-risk-analysis/index.html | M5: Risk analysis is the most direct HIPAA citation for assessment-oriented rows.
A6: REQ-20-HIPAA | B6: 1704.03b1Organizational.12 | C6: =COUNTIFS(Normalized_Tuples!$E:$E,$A6,Normalized_Tuples!$F:$F,$B6) -> 2 | D6: Risk Assessment; Risk Management | E6: Operational, Policy | F6: HITRUST e1.csv | G6: Many:1, Many:Many | H6: 45 CFR § 164.308(a)(1)(ii)(B) | I6: Security Management Process — Risk Management | J6: Direct | K6: Control context aligns to reducing identified risks and vulnerabilities to a reasonable and appropriate level. | L6: https://www.ecfr.gov/current/title-45/subtitle-A/subchapter-C/part-164/section-164.308 | https://www.hhs.gov/sites/default/files/ocr/privacy/hipaa/administrative/combined/hipaa-simplification-201303.pdf | https://www.hhs.gov/hipaa/for-professionals/security/guidance/guidance-risk-analysis/index.html | M6: Used for policy and operational rows focused on treatment/mitigation of identified risks.
A7: REQ-26-HIPAA | B7: 10.01d1System.10 | C7: =COUNTIFS(Normalized_Tuples!$E:$E,$A7,Normalized_Tuples!$F:$F,$B7) -> 2 | D7: Password and Multi-Factor Authentication; Passwords for All In-Scope Production Systems | E7: Policy, Configuration | F7: HITRUST e1.csv | G7: 1:Many, 1:1 | H7: 45 CFR § 164.308(a)(5)(ii)(D) | 45 CFR § 164.312(d) | 45 CFR § 164.312(a)(1) | I7: Security Awareness and Training — Password Management | Person or Entity Authentication | Access Control | J7: Composite | K7: Action item explicitly combines password controls with MFA, so both password management and authentication verification are cited. | Password configuration evidence most directly aligns to password-management requirements and the broader access-control standard. | L7: https://www.ecfr.gov/current/title-45/subtitle-A/subchapter-C/part-164/section-164.308 | https://www.ecfr.gov/current/title-45/subtitle-A/subchapter-C/part-164/section-164.312 | https://www.hhs.gov/sites/default/files/ocr/privacy/hipaa/administrative/securityrule/adminsafeguards.pdf | https://www.hhs.gov/hipaa/for-professionals/compliance-enforcement/audit/protocol/index.html | M7: Covers password creation/change/safeguarding and MFA-style authentication evidence. | This row is password-configuration evidence; MFA is not the primary evidence artifact here.
A8: REQ-29-HIPAA | B8: 11.01e1System.2 | C8: =COUNTIFS(Normalized_Tuples!$E:$E,$A8,Normalized_Tuples!$F:$F,$B8) -> 2 | D8: Access Control; Access Review Documentation | E8: Policy, Sample | F8: HITRUST e1.csv | G8: Many:1, 1:1 | H8: 45 CFR § 164.308(a)(4)(ii)(C) | I8: Information Access Management — Access Establishment and Modification | J8: Direct | K8: Access-review documentation aligns directly to the requirement to establish, document, review, and modify user rights of access. | L8: https://www.ecfr.gov/current/title-45/subtitle-A/subchapter-C/part-164/section-164.308 | https://www.hhs.gov/hipaa/for-professionals/compliance-enforcement/audit/protocol/index.html | https://www.hhs.gov/sites/default/files/ocr/privacy/hipaa/administrative/securityrule/adminsafeguards.pdf | M8: Used for both access-review evidence and broader policy statements that emphasize periodic review/modification.
A9: REQ-31-HIPAA | B9: 11143.02i1Organizational.3 | C9: =COUNTIFS(Normalized_Tuples!$E:$E,$A9,Normalized_Tuples!$F:$F,$B9) -> 2 | D9: All Terminated Employees During the Review Period [INSERT EXAM PERIOD]; Employee Termination Ticket | E9: Population, Sample | F9: HITRUST e1.csv | G9: Many:1, 1:1 | H9: 45 CFR § 164.308(a)(3)(ii)(C) | 45 CFR § 164.316(b)(1) | I9: Workforce Security — Termination Procedures | Documentation | J9: Composite | K9: Termination tickets/population evidence align directly to terminating access and documenting the action taken. | L9: https://www.ecfr.gov/current/title-45/subtitle-A/subchapter-C/part-164/section-164.308 | https://www.ecfr.gov/current/title-45/subtitle-A/subchapter-C/part-164/section-164.316 | https://www.hhs.gov/hipaa/for-professionals/compliance-enforcement/audit/protocol/index.html | https://www.hhs.gov/hipaa/for-professionals/security/guidance/cybersecurity-newsletter-summer-2019/index.html | M9: Documentation is added because the row is explicit evidence that access-removal events were carried out and recorded.
A10: REQ-33-HIPAA | B10: 04.01x1Organizational.5 | C10: =COUNTIFS(Normalized_Tuples!$E:$E,$A10,Normalized_Tuples!$F:$F,$B10) -> 2 | D10: Data Encryption at Rest; Encryption In Transit (Ex. TLS Protocols) | E10: Configuration | F10: HITRUST e1.csv | G10: Many:Many | H10: 45 CFR § 164.312(a)(2)(iv) | 45 CFR § 164.312(e)(2)(ii) | I10: Access Control — Encryption and Decryption | Transmission Security — Encryption | J10: Direct | K10: At-rest encryption evidence aligns directly to the encryption/decryption implementation specification under access control. | Transmission-encryption evidence aligns directly to the transmission-security encryption implementation specification. | L10: https://www.ecfr.gov/current/title-45/subtitle-A/subchapter-C/part-164/section-164.312 | https://www.hhs.gov/hipaa/for-professionals/compliance-enforcement/audit/protocol/index.html | https://www.hhs.gov/sites/default/files/ocr/privacy/hipaa/administrative/combined/hipaa-simplification-201303.pdf | https://www.hhs.gov/hipaa/for-professionals/security/guidance/cybersecurity-newsletter-january-2026/index.html | M10: Used when the shared action item is explicitly at-rest encryption. | Used when the shared action item is explicitly in-transit encryption.
A11: REQ-35-HIPAA | B11: 04.01x1Organizational.5 | C11: =COUNTIFS(Normalized_Tuples!$E:$E,$A11,Normalized_Tuples!$F:$F,$B11) -> 2 | D11: Data Encryption at Rest; Encryption In Transit (Ex. TLS Protocols) | E11: Configuration | F11: HITRUST e1.csv | G11: Many:Many | H11: 45 CFR § 164.312(a)(2)(iv) | 45 CFR § 164.312(e)(2)(ii) | I11: Access Control — Encryption and Decryption | Transmission Security — Encryption | J11: Best-fit | Direct | K11: This internal control ID also appears on an at-rest encryption row in the source spreadsheets, so the row context points to at-rest encryption even though the same control family also covers transmission encryption elsewhere. | Action item explicitly addresses encryption in transit. | L11: https://www.ecfr.gov/current/title-45/subtitle-A/subchapter-C/part-164/section-164.312 | https://www.hhs.gov/hipaa/for-professionals/compliance-enforcement/audit/protocol/index.html | https://www.hhs.gov/sites/default/files/ocr/privacy/hipaa/administrative/combined/hipaa-simplification-201303.pdf | https://www.hhs.gov/hipaa/for-professionals/security/guidance/cybersecurity-newsletter-january-2026/index.html | M11: Row-context mapping takes precedence over the broader internal control family. | Used for transport/TLS evidence.
A12: REQ-55-HIPAA | B12: 06.09b1System.2 | C12: =COUNTIFS(Normalized_Tuples!$E:$E,$A12,Normalized_Tuples!$F:$F,$B12) -> 2 | D12: All Software and Infrastructure Production Changes During the Review Period [INSERT EXAM PERIOD]; Software/Infrastructure Production Change Ticket | E12: Population, Sample | F12: HITRUST e1.csv | G12: Many:Many, 1:1 | H12: 45 CFR § 164.308(a)(8) | 45 CFR § 164.316(b)(1) | I12: Evaluation | Documentation | J12: Best-fit composite | K12: Production-change tickets/population evidence are not a named HIPAA specification, but they are strong evidence of evaluating and documenting operational changes affecting ePHI safeguards. | L12: https://www.ecfr.gov/current/title-45/subtitle-A/subchapter-C/part-164/section-164.308 | https://www.ecfr.gov/current/title-45/subtitle-A/subchapter-C/part-164/section-164.316 | https://www.hhs.gov/hipaa/for-professionals/security/guidance/cybersecurity-newsletter-january-2026/index.html | https://www.hhs.gov/hipaa/for-professionals/security/guidance/guidance-risk-analysis/index.html | M12: Best-fit evidence mapping; HIPAA does not mandate a particular ticketing mechanism.
A13: REQ-61-HIPAA | B13: 1616.09l1Organizational.16 | C13: =COUNTIFS(Normalized_Tuples!$E:$E,$A13,Normalized_Tuples!$F:$F,$B13) -> 2 | D13: Backups; Completed Production Data Backup Test | E13: Policy, Operational | F13: HITRUST e1.csv | G13: Many:1, 1:1 | H13: 45 CFR § 164.308(a)(7)(ii)(A) | 45 CFR § 164.308(a)(7)(ii)(D) | I13: Contingency Plan — Data Backup Plan | Contingency Plan — Testing and Revision Procedure | J13: Composite | Direct | K13: This internal control appears on general backup-policy rows and explicit backup-test rows, so both backup-plan and test/revision citations are included. | A completed backup test aligns directly to periodic testing/revision of contingency plans. | L13: https://www.ecfr.gov/current/title-45/subtitle-A/subchapter-C/part-164/section-164.308 | https://www.hhs.gov/hipaa/for-professionals/compliance-enforcement/audit/protocol/index.html | https://www.hhs.gov/hipaa/for-professionals/security/guidance/cybersecurity/ransomware-fact-sheet/index.html | M13: Broader than a single implementation specification because the source spreadsheet uses the same control across planning and testing evidence. | Used for explicit backup-test evidence.
... A104: REQ-995-HIPAA | B104: 1704.03b1Organizational.12 | C104: =COUNTIFS(Normalized_Tuples!$E:$E,$A104,Normalized_Tuples!$F:$F,$B104) -> 1 | D104: All Software and Infrastructure Production Changes During the Review Period [INSERT EXAM PERIOD] | E104: Population | F104: HITRUST e1.csv | G104: Many:Many | H104: 45 CFR § 164.308(a)(8) | 45 CFR § 164.316(b)(1) | I104: Evaluation | Documentation | J104: Best-fit composite | K104: Generic population/evidence control used to show production changes during the review period. | L104: https://www.ecfr.gov/current/title-45/subtitle-A/subchapter-C/part-164/section-164.308 | https://www.ecfr.gov/current/title-45/subtitle-A/subchapter-C/part-164/section-164.316 | https://www.hhs.gov/hipaa/for-professionals/security/guidance/cybersecurity-newsletter-january-2026/index.html | https://www.hhs.gov/hipaa/for-professionals/security/guidance/guidance-risk-analysis/index.html | M104: Internal control is generic; citation follows the specific evidence row context.

Sheet HIPAA_45CFR_Mapping
A1: HIPAA → 45 CFR mapping register (action-item context)
A3: HIPAA Control | B3: Action Item | C3: Tuple_Count | D3: HITRUST_e1_Controls | E3: Categories | F3: Reference_IDs | G3: HIPAA 45 CFR Citation(s) | H3: HIPAA Standard / Spec | I3: 45 CFR Mapping Confidence | J3: 45 CFR Mapping Basis | K3: Authoritative Public Source URL(s) | L3: 45 CFR Notes
A4: REQ-1-HIPAA | B4: Information Security | C4: 1 | D4: 0113.04a1Organizational.2 | E4: Policy | F4: ER-57 | G4: 45 CFR § 164.316(a); 45 CFR § 164.316(b)(1) | H4: Policies and Procedures; Documentation | I4: Best-fit (broad policy control) | J4: Internal control/action item is a general information-security policy repository rather than a single named HIPAA implementation specification; mapped to the Security Rule's policies/procedures and documentation requirements. | K4: https://www.ecfr.gov/current/title-45/subtitle-A/subchapter-C/part-164/section-164.316 | https://www.hhs.gov/sites/default/files/ocr/privacy/hipaa/administrative/securityrule/pprequirements.pdf | https://www.hhs.gov/ocr/privacy/hipaa/administrative/securityrule/index.html | L4: Used as the umbrella HIPAA citation for documented security policies. This is broader than any single safeguard requirement.
A5: REQ-1-HIPAA | B5: Information Security Policy Repository | C5: 1 | D5: 0113.04a1Organizational.2 | E5: Operational | F5: ER-56 | G5: 45 CFR § 164.316(a); 45 CFR § 164.316(b)(1) | H5: Policies and Procedures; Documentation | I5: Best-fit (broad policy control) | J5: Internal control/action item is a general information-security policy repository rather than a single named HIPAA implementation specification; mapped to the Security Rule's policies/procedures and documentation requirements. | K5: https://www.ecfr.gov/current/title-45/subtitle-A/subchapter-C/part-164/section-164.316 | https://www.hhs.gov/sites/default/files/ocr/privacy/hipaa/administrative/securityrule/pprequirements.pdf | https://www.hhs.gov/ocr/privacy/hipaa/administrative/securityrule/index.html | L5: Used as the umbrella HIPAA citation for documented security policies. This is broader than any single safeguard requirement.
A6: REQ-102-HIPAA | B6: List of All Production Systems (Servers, VMs, Data Stores) | C6: 3 | D6: 07.07a1Organizational.8, 0701.07a1Organizational.7, 0701.07a1Organizational.8 | E6: Configuration | F6: ER-12 | G6: 45 CFR § 164.308(a)(1)(ii)(A) | H6: Security Management Process — Risk Analysis | I6: Best-fit | J6: HIPAA does not expressly mandate an IT asset inventory, but OCR guidance says a comprehensive technology asset inventory and ePHI data-flow diagrams are valuable tools for an accurate and thorough risk analysis. | K6: https://www.ecfr.gov/current/title-45/subtitle-A/subchapter-C/part-164/section-164.308 | https://www.hhs.gov/hipaa/for-professionals/security/guidance/guidance-risk-analysis/index.html | https://www.hhs.gov/hipaa/for-professionals/security/guidance/cybersecurity-newsletter-october-2024/index.html | L6: Mapped as supporting evidence for risk analysis rather than as a standalone named HIPAA inventory control.
A7: REQ-109-HIPAA | B7: Asset Custody Log | C7: 2 | D7: 0701.07a1Organizational.8, 0704.07a1Organizational.8 | E7: Operational | F7: ER-271 | G7: 45 CFR § 164.310(d)(2)(iii) | H7: Device and Media Controls — Accountability | I7: Direct | J7: Asset custody logs align directly to maintaining a record of the movements of hardware/electronic media and the person responsible. | K7: https://www.ecfr.gov/current/title-45/subtitle-A/subchapter-C/part-164/section-164.310 | https://www.hhs.gov/hipaa/for-professionals/compliance-enforcement/audit/protocol/index.html | https://www.hhs.gov/sites/default/files/ocr/privacy/hipaa/administrative/combined/hipaa-simplification-201303.pdf | L7: Used for custody/chain-of-responsibility evidence.
A8: REQ-110-HIPAA | B8: Risk Assessment | C8: 1 | D8: 1704.03b1Organizational.12 | E8: Operational | F8: ER-105 | G8: 45 CFR § 164.308(a)(1)(ii)(A) | H8: Security Management Process — Risk Analysis | I8: Best-fit | J8: The source spreadsheet only exposes an internal control ID on the Risk Assessment action item, so the closest authoritative HIPAA citation is Risk Analysis. | K8: https://www.ecfr.gov/current/title-45/subtitle-A/subchapter-C/part-164/section-164.308 | https://www.hhs.gov/hipaa/for-professionals/security/guidance/guidance-risk-analysis/index.html | https://www.hhs.gov/sites/default/files/ocr/privacy/hipaa/administrative/combined/hipaa-simplification-201303.pdf | L8: Matched by action-item semantics because the internal control itself is not labeled with an official HIPAA section.
A9: REQ-12-HIPAA | B9: Information Security | C9: 1 | D9: 0113.04a1Organizational.2 | E9: Policy | F9: ER-57 | G9: 45 CFR § 164.308(a)(5) | H9: Security Awareness and Training | I9: Direct | J9: Action item and control context align to workforce security-awareness training for new hires. | K9: https://www.ecfr.gov/current/title-45/subtitle-A/subchapter-C/part-164/section-164.308 | https://www.hhs.gov/sites/default/files/ocr/privacy/hipaa/administrative/combined/hipaa-simplification-201303.pdf | https://www.hhs.gov/sites/default/files/ocr/privacy/hipaa/administrative/securityrule/adminsafeguards.pdf | L9: Mapped at the standard level because the spreadsheet does not break new-hire training into the more granular addressable sub-specifications.
A10: REQ-12-HIPAA | B10: Information Security Policy Repository | C10: 1 | D10: 0113.04a1Organizational.2 | E10: Operational | F10: ER-56 | G10: 45 CFR § 164.308(a)(5) | H10: Security Awareness and Training | I10: Direct | J10: Action item and control context align to workforce security-awareness training for new hires. | K10: https://www.ecfr.gov/current/title-45/subtitle-A/subchapter-C/part-164/section-164.308 | https://www.hhs.gov/sites/default/files/ocr/privacy/hipaa/administrative/combined/hipaa-simplification-201303.pdf | https://www.hhs.gov/sites/default/files/ocr/privacy/hipaa/administrative/securityrule/adminsafeguards.pdf | L10: Mapped at the standard level because the spreadsheet does not break new-hire training into the more granular addressable sub-specifications.
A11: REQ-12-HIPAA | B11: New Hire Security Awareness Training | C11: 3 | D11: 13.02e1Organizational.6, 1308.09j1Organizational.5.a, 13998.02e1Organizational.2 | E11: Sample | F11: ER-33 | G11: 45 CFR § 164.308(a)(5) | H11: Security Awareness and Training | I11: Direct | J11: Action item and control context align to workforce security-awareness training for new hires. | K11: https://www.ecfr.gov/current/title-45/subtitle-A/subchapter-C/part-164/section-164.308 | https://www.hhs.gov/sites/default/files/ocr/privacy/hipaa/administrative/combined/hipaa-simplification-201303.pdf | https://www.hhs.gov/sites/default/files/ocr/privacy/hipaa/administrative/securityrule/adminsafeguards.pdf | L11: Mapped at the standard level because the spreadsheet does not break new-hire training into the more granular addressable sub-specifications.
